<?xml version="1.0" ?>
<!-- =================================================================================== -->
<!-- |    This document was autogenerated by xacro from /Users/yasu/3d-soft-trunk/urdf/2segment.urdf.xacro | -->
<!-- |    EDITING THIS FILE BY HAND IS NOT RECOMMENDED                                 | -->
<!-- =================================================================================== -->
<!-- This file has been generated automatically from create_xacro.cpp, do not edit by hand -->
<robot name="2segment" xmlns:xacro="http://www.ros.org/wiki/xacro">
	<material name="white">
		<color rgba="1 1 1 1"/>
	</material>
	<material name="green">
		<color rgba="0.2 1 0.2 0.8"/>
	</material>
	<link name="prism_base_link">
		<!--since the RBDL needs a inertial info for each link, just assign a really small value to links where we don't have to consider inertia.-->	<visual>
			<geometry>
				<cylinder length="0.15" radius="0.04"/>
			</geometry>
			<material name="white"/>
		</visual>
		<origin xyz="0 0 0"/>	
		<inertial>
			<mass value="0.00001"/>
			<inertia ixx="0.00001" ixy="0.0000" ixz="0.0000" iyy="0.00001" iyz="0.0000" izz="0.00001"/>
		</inertial>
	</link>
	<joint name="prism_joint" type="prismatic">
		<parent link="prism_base_link"/>
		<child link="prism_lower_link"/>
		<axis xyz="0 0 1"/>
		<origin xyz="0 0 0"/>
		<limit effort="1000" lower="0" upper="0.08" velocity="1000"/>
	</joint>
	<link name="prism_lower_link">
		<!--since the RBDL needs a inertial info for each link, just assign a really small value to links where we don't have to consider inertia.-->	<visual>
			<geometry>
				<cylinder length="0.15" radius="0.02"/>
			</geometry>
			
			<material name="white"/>
		</visual>
		<origin xyz="0 0 0"/>	
		<inertial>
			<mass value="0.1"/>
			<inertia ixx="0.00001" ixy="0.0000" ixz="0.0000" iyy="0.00001" iyz="0.0000" izz="0.00001"/>
		</inertial>
	</link>
	<joint name="fixed_joint" type="fixed">
		<parent link="prism_lower_link"/>
		<child link="base_link"/>
	</joint>
	<link name="base_link">
		<!--since the RBDL needs a inertial info for each link, just assign a really small value to links where we don't have to consider inertia.-->
		<inertial>
			<mass value="0.00001"/>
			<inertia ixx="0.00001" ixy="0.0000" ixz="0.0000" iyy="0.00001" iyz="0.0000" izz="0.00001"/>
		</inertial>
	</link>
	<!--creates a (pseudo) ball joint, called from the PCC macro..-->
	<joint name="seg0_sec0-ball-ball-joint_x_joint" type="revolute">
		<parent link="base_link"/>
		<child link="seg0_sec0-ball-ball-joint_link_0"/>
		<axis xyz="1 0 0"/>
		<limit effort="1000" lower="-1.57075" upper="1.57075" velocity="1000"/>
	</joint>
	<link name="seg0_sec0-ball-ball-joint_link_0">
		<!--since the RBDL needs a inertial info for each link, just assign a really small value to links where we don't have to consider inertia.-->
		<inertial>
			<mass value="0.00001"/>
			<inertia ixx="0.00001" ixy="0.0000" ixz="0.0000" iyy="0.00001" iyz="0.0000" izz="0.00001"/>
		</inertial>
	</link>
	<joint name="seg0_sec0-ball-ball-joint_y_joint" type="revolute">
		<parent link="seg0_sec0-ball-ball-joint_link_0"/>
		<child link="seg0_sec0-ball-ball-joint_link_1"/>
		<axis xyz="0 1 0"/>
		<limit effort="1000" lower="-1.57075" upper="1.57075" velocity="1000"/>
	</joint>
	<link name="seg0_sec0-ball-ball-joint_link_1">
		<!--since the RBDL needs a inertial info for each link, just assign a really small value to links where we don't have to consider inertia.-->
		<inertial>
			<mass value="0.00001"/>
			<inertia ixx="0.00001" ixy="0.0000" ixz="0.0000" iyy="0.00001" iyz="0.0000" izz="0.00001"/>
		</inertial>
		<visual>
			<geometry>
				<box size="0.0024000000000000002 0.0024000000000000002 0.0024000000000000002"/>
			</geometry>
			<material name="white"/>
		</visual>
	</link>
	<joint name="seg0_sec0-ball-ball-joint_z_joint" type="revolute">
		<parent link="seg0_sec0-ball-ball-joint_link_1"/>
		<child link="seg0_sec0-a"/>
		<axis xyz="0 0 1"/>
		<limit effort="1000" lower="-1.57075" upper="1.57075" velocity="1000"/>
	</joint>
	<link name="seg0_sec0-a">
		<!--since the RBDL needs a inertial info for each link, just assign a really small value to links where we don't have to consider inertia.-->
		<inertial>
			<mass value="0.00001"/>
			<inertia ixx="0.00001" ixy="0.0000" ixz="0.0000" iyy="0.00001" iyz="0.0000" izz="0.00001"/>
		</inertial>
	</link>
	<joint name="seg0_sec0-a-b_joint" type="prismatic">
		<parent link="seg0_sec0-a"/>
		<child link="seg0_sec0-b"/>
		<axis xyz="0 0 -1"/>
		<origin xyz="0 0 0.012"/>
		<limit effort="1000" lower="0" upper="0.012" velocity="1000"/>
	</joint>
	<link name="seg0_sec0-b">
		<visual>
			<geometry>
				<cylinder length="0.024" radius="0.016"/>
			</geometry>
			<!-- <origin xyz="0 0 ${length/2}"/> -->
			<material name="green"/>
		</visual>
		<inertial>
			<mass value="0.2"/>
			<inertia ixx="0.0001" ixy="0.000" ixz="0.000" iyy="0.0001" iyz="0.000" izz="0.0001"/>
		</inertial>
	</link>
	<joint name="seg0_sec0-b-seg0_sec0-1_connect_joint" type="prismatic">
		<parent link="seg0_sec0-b"/>
		<child link="seg0_sec0-1_connect"/>
		<axis xyz="0 0 -1"/>
		<origin xyz="0 0 0.012"/>
		<limit effort="1000" lower="0" upper="0.012" velocity="1000"/>
	</joint>
	<link name="seg0_sec0-1_connect">
		<!--since the RBDL needs a inertial info for each link, just assign a really small value to links where we don't have to consider inertia.-->
		<inertial>
			<mass value="0.00001"/>
			<inertia ixx="0.00001" ixy="0.0000" ixz="0.0000" iyy="0.00001" iyz="0.0000" izz="0.00001"/>
		</inertial>
	</link>
	<!--creates a (pseudo) ball joint, called from the PCC macro..-->
	<joint name="seg0_sec1-ball-ball-joint_x_joint" type="revolute">
		<parent link="seg0_sec0-1_connect"/>
		<child link="seg0_sec1-ball-ball-joint_link_0"/>
		<axis xyz="1 0 0"/>
		<limit effort="1000" lower="-1.57075" upper="1.57075" velocity="1000"/>
	</joint>
	<link name="seg0_sec1-ball-ball-joint_link_0">
		<!--since the RBDL needs a inertial info for each link, just assign a really small value to links where we don't have to consider inertia.-->
		<inertial>
			<mass value="0.00001"/>
			<inertia ixx="0.00001" ixy="0.0000" ixz="0.0000" iyy="0.00001" iyz="0.0000" izz="0.00001"/>
		</inertial>
	</link>
	<joint name="seg0_sec1-ball-ball-joint_y_joint" type="revolute">
		<parent link="seg0_sec1-ball-ball-joint_link_0"/>
		<child link="seg0_sec1-ball-ball-joint_link_1"/>
		<axis xyz="0 1 0"/>
		<limit effort="1000" lower="-1.57075" upper="1.57075" velocity="1000"/>
	</joint>
	<link name="seg0_sec1-ball-ball-joint_link_1">
		<!--since the RBDL needs a inertial info for each link, just assign a really small value to links where we don't have to consider inertia.-->
		<inertial>
			<mass value="0.00001"/>
			<inertia ixx="0.00001" ixy="0.0000" ixz="0.0000" iyy="0.00001" iyz="0.0000" izz="0.00001"/>
		</inertial>
		<visual>
			<geometry>
				<box size="0.0024000000000000002 0.0024000000000000002 0.0024000000000000002"/>
			</geometry>
			<material name="white"/>
		</visual>
	</link>
	<joint name="seg0_sec1-ball-ball-joint_z_joint" type="revolute">
		<parent link="seg0_sec1-ball-ball-joint_link_1"/>
		<child link="seg0_sec1-a"/>
		<axis xyz="0 0 1"/>
		<limit effort="1000" lower="-1.57075" upper="1.57075" velocity="1000"/>
	</joint>
	<link name="seg0_sec1-a">
		<!--since the RBDL needs a inertial info for each link, just assign a really small value to links where we don't have to consider inertia.-->
		<inertial>
			<mass value="0.00001"/>
			<inertia ixx="0.00001" ixy="0.0000" ixz="0.0000" iyy="0.00001" iyz="0.0000" izz="0.00001"/>
		</inertial>
	</link>
	<joint name="seg0_sec1-a-b_joint" type="prismatic">
		<parent link="seg0_sec1-a"/>
		<child link="seg0_sec1-b"/>
		<axis xyz="0 0 -1"/>
		<origin xyz="0 0 0.012"/>
		<limit effort="1000" lower="0" upper="0.012" velocity="1000"/>
	</joint>
	<link name="seg0_sec1-b">
		<visual>
			<geometry>
				<cylinder length="0.024" radius="0.0156"/>
			</geometry>
			<!-- <origin xyz="0 0 ${length/2}"/> -->
			<material name="green"/>
		</visual>
		<inertial>
			<mass value="0.2"/>
			<inertia ixx="0.0001" ixy="0.000" ixz="0.000" iyy="0.0001" iyz="0.000" izz="0.0001"/>
		</inertial>
	</link>
	<joint name="seg0_sec1-b-seg0_sec1-2_connect_joint" type="prismatic">
		<parent link="seg0_sec1-b"/>
		<child link="seg0_sec1-2_connect"/>
		<axis xyz="0 0 -1"/>
		<origin xyz="0 0 0.012"/>
		<limit effort="1000" lower="0" upper="0.012" velocity="1000"/>
	</joint>
	<link name="seg0_sec1-2_connect">
		<!--since the RBDL needs a inertial info for each link, just assign a really small value to links where we don't have to consider inertia.-->
		<inertial>
			<mass value="0.00001"/>
			<inertia ixx="0.00001" ixy="0.0000" ixz="0.0000" iyy="0.00001" iyz="0.0000" izz="0.00001"/>
		</inertial>
	</link>
	<!--creates a (pseudo) ball joint, called from the PCC macro..-->
	<joint name="seg0_sec2-ball-ball-joint_x_joint" type="revolute">
		<parent link="seg0_sec1-2_connect"/>
		<child link="seg0_sec2-ball-ball-joint_link_0"/>
		<axis xyz="1 0 0"/>
		<limit effort="1000" lower="-1.57075" upper="1.57075" velocity="1000"/>
	</joint>
	<link name="seg0_sec2-ball-ball-joint_link_0">
		<!--since the RBDL needs a inertial info for each link, just assign a really small value to links where we don't have to consider inertia.-->
		<inertial>
			<mass value="0.00001"/>
			<inertia ixx="0.00001" ixy="0.0000" ixz="0.0000" iyy="0.00001" iyz="0.0000" izz="0.00001"/>
		</inertial>
	</link>
	<joint name="seg0_sec2-ball-ball-joint_y_joint" type="revolute">
		<parent link="seg0_sec2-ball-ball-joint_link_0"/>
		<child link="seg0_sec2-ball-ball-joint_link_1"/>
		<axis xyz="0 1 0"/>
		<limit effort="1000" lower="-1.57075" upper="1.57075" velocity="1000"/>
	</joint>
	<link name="seg0_sec2-ball-ball-joint_link_1">
		<!--since the RBDL needs a inertial info for each link, just assign a really small value to links where we don't have to consider inertia.-->
		<inertial>
			<mass value="0.00001"/>
			<inertia ixx="0.00001" ixy="0.0000" ixz="0.0000" iyy="0.00001" iyz="0.0000" izz="0.00001"/>
		</inertial>
		<visual>
			<geometry>
				<box size="0.0024000000000000002 0.0024000000000000002 0.0024000000000000002"/>
			</geometry>
			<material name="white"/>
		</visual>
	</link>
	<joint name="seg0_sec2-ball-ball-joint_z_joint" type="revolute">
		<parent link="seg0_sec2-ball-ball-joint_link_1"/>
		<child link="seg0_sec2-a"/>
		<axis xyz="0 0 1"/>
		<limit effort="1000" lower="-1.57075" upper="1.57075" velocity="1000"/>
	</joint>
	<link name="seg0_sec2-a">
		<!--since the RBDL needs a inertial info for each link, just assign a really small value to links where we don't have to consider inertia.-->
		<inertial>
			<mass value="0.00001"/>
			<inertia ixx="0.00001" ixy="0.0000" ixz="0.0000" iyy="0.00001" iyz="0.0000" izz="0.00001"/>
		</inertial>
	</link>
	<joint name="seg0_sec2-a-b_joint" type="prismatic">
		<parent link="seg0_sec2-a"/>
		<child link="seg0_sec2-b"/>
		<axis xyz="0 0 -1"/>
		<origin xyz="0 0 0.012"/>
		<limit effort="1000" lower="0" upper="0.012" velocity="1000"/>
	</joint>
	<link name="seg0_sec2-b">
		<visual>
			<geometry>
				<cylinder length="0.024" radius="0.0152"/>
			</geometry>
			<!-- <origin xyz="0 0 ${length/2}"/> -->
			<material name="green"/>
		</visual>
		<inertial>
			<mass value="0.2"/>
			<inertia ixx="0.0001" ixy="0.000" ixz="0.000" iyy="0.0001" iyz="0.000" izz="0.0001"/>
		</inertial>
	</link>
	<joint name="seg0_sec2-b-seg0_sec2-3_connect_joint" type="prismatic">
		<parent link="seg0_sec2-b"/>
		<child link="seg0_sec2-3_connect"/>
		<axis xyz="0 0 -1"/>
		<origin xyz="0 0 0.012"/>
		<limit effort="1000" lower="0" upper="0.012" velocity="1000"/>
	</joint>
	<link name="seg0_sec2-3_connect">
		<!--since the RBDL needs a inertial info for each link, just assign a really small value to links where we don't have to consider inertia.-->
		<inertial>
			<mass value="0.00001"/>
			<inertia ixx="0.00001" ixy="0.0000" ixz="0.0000" iyy="0.00001" iyz="0.0000" izz="0.00001"/>
		</inertial>
	</link>
	<!--creates a (pseudo) ball joint, called from the PCC macro..-->
	<joint name="seg0_sec3-ball-ball-joint_x_joint" type="revolute">
		<parent link="seg0_sec2-3_connect"/>
		<child link="seg0_sec3-ball-ball-joint_link_0"/>
		<axis xyz="1 0 0"/>
		<limit effort="1000" lower="-1.57075" upper="1.57075" velocity="1000"/>
	</joint>
	<link name="seg0_sec3-ball-ball-joint_link_0">
		<!--since the RBDL needs a inertial info for each link, just assign a really small value to links where we don't have to consider inertia.-->
		<inertial>
			<mass value="0.00001"/>
			<inertia ixx="0.00001" ixy="0.0000" ixz="0.0000" iyy="0.00001" iyz="0.0000" izz="0.00001"/>
		</inertial>
	</link>
	<joint name="seg0_sec3-ball-ball-joint_y_joint" type="revolute">
		<parent link="seg0_sec3-ball-ball-joint_link_0"/>
		<child link="seg0_sec3-ball-ball-joint_link_1"/>
		<axis xyz="0 1 0"/>
		<limit effort="1000" lower="-1.57075" upper="1.57075" velocity="1000"/>
	</joint>
	<link name="seg0_sec3-ball-ball-joint_link_1">
		<!--since the RBDL needs a inertial info for each link, just assign a really small value to links where we don't have to consider inertia.-->
		<inertial>
			<mass value="0.00001"/>
			<inertia ixx="0.00001" ixy="0.0000" ixz="0.0000" iyy="0.00001" iyz="0.0000" izz="0.00001"/>
		</inertial>
		<visual>
			<geometry>
				<box size="0.0024000000000000002 0.0024000000000000002 0.0024000000000000002"/>
			</geometry>
			<material name="white"/>
		</visual>
	</link>
	<joint name="seg0_sec3-ball-ball-joint_z_joint" type="revolute">
		<parent link="seg0_sec3-ball-ball-joint_link_1"/>
		<child link="seg0_sec3-a"/>
		<axis xyz="0 0 1"/>
		<limit effort="1000" lower="-1.57075" upper="1.57075" velocity="1000"/>
	</joint>
	<link name="seg0_sec3-a">
		<!--since the RBDL needs a inertial info for each link, just assign a really small value to links where we don't have to consider inertia.-->
		<inertial>
			<mass value="0.00001"/>
			<inertia ixx="0.00001" ixy="0.0000" ixz="0.0000" iyy="0.00001" iyz="0.0000" izz="0.00001"/>
		</inertial>
	</link>
	<joint name="seg0_sec3-a-b_joint" type="prismatic">
		<parent link="seg0_sec3-a"/>
		<child link="seg0_sec3-b"/>
		<axis xyz="0 0 -1"/>
		<origin xyz="0 0 0.012"/>
		<limit effort="1000" lower="0" upper="0.012" velocity="1000"/>
	</joint>
	<link name="seg0_sec3-b">
		<visual>
			<geometry>
				<cylinder length="0.024" radius="0.014800000000000002"/>
			</geometry>
			<!-- <origin xyz="0 0 ${length/2}"/> -->
			<material name="green"/>
		</visual>
		<inertial>
			<mass value="0.2"/>
			<inertia ixx="0.0001" ixy="0.000" ixz="0.000" iyy="0.0001" iyz="0.000" izz="0.0001"/>
		</inertial>
	</link>
	<joint name="seg0_sec3-b-seg0_sec3-4_connect_joint" type="prismatic">
		<parent link="seg0_sec3-b"/>
		<child link="seg0_sec3-4_connect"/>
		<axis xyz="0 0 -1"/>
		<origin xyz="0 0 0.012"/>
		<limit effort="1000" lower="0" upper="0.012" velocity="1000"/>
	</joint>
	<link name="seg0_sec3-4_connect">
		<!--since the RBDL needs a inertial info for each link, just assign a really small value to links where we don't have to consider inertia.-->
		<inertial>
			<mass value="0.00001"/>
			<inertia ixx="0.00001" ixy="0.0000" ixz="0.0000" iyy="0.00001" iyz="0.0000" izz="0.00001"/>
		</inertial>
	</link>
	<!--creates a (pseudo) ball joint, called from the PCC macro..-->
	<joint name="seg0_sec4-ball-ball-joint_x_joint" type="revolute">
		<parent link="seg0_sec3-4_connect"/>
		<child link="seg0_sec4-ball-ball-joint_link_0"/>
		<axis xyz="1 0 0"/>
		<limit effort="1000" lower="-1.57075" upper="1.57075" velocity="1000"/>
	</joint>
	<link name="seg0_sec4-ball-ball-joint_link_0">
		<!--since the RBDL needs a inertial info for each link, just assign a really small value to links where we don't have to consider inertia.-->
		<inertial>
			<mass value="0.00001"/>
			<inertia ixx="0.00001" ixy="0.0000" ixz="0.0000" iyy="0.00001" iyz="0.0000" izz="0.00001"/>
		</inertial>
	</link>
	<joint name="seg0_sec4-ball-ball-joint_y_joint" type="revolute">
		<parent link="seg0_sec4-ball-ball-joint_link_0"/>
		<child link="seg0_sec4-ball-ball-joint_link_1"/>
		<axis xyz="0 1 0"/>
		<limit effort="1000" lower="-1.57075" upper="1.57075" velocity="1000"/>
	</joint>
	<link name="seg0_sec4-ball-ball-joint_link_1">
		<!--since the RBDL needs a inertial info for each link, just assign a really small value to links where we don't have to consider inertia.-->
		<inertial>
			<mass value="0.00001"/>
			<inertia ixx="0.00001" ixy="0.0000" ixz="0.0000" iyy="0.00001" iyz="0.0000" izz="0.00001"/>
		</inertial>
		<visual>
			<geometry>
				<box size="0.0024000000000000002 0.0024000000000000002 0.0024000000000000002"/>
			</geometry>
			<material name="white"/>
		</visual>
	</link>
	<joint name="seg0_sec4-ball-ball-joint_z_joint" type="revolute">
		<parent link="seg0_sec4-ball-ball-joint_link_1"/>
		<child link="seg0_sec4-a"/>
		<axis xyz="0 0 1"/>
		<limit effort="1000" lower="-1.57075" upper="1.57075" velocity="1000"/>
	</joint>
	<link name="seg0_sec4-a">
		<!--since the RBDL needs a inertial info for each link, just assign a really small value to links where we don't have to consider inertia.-->
		<inertial>
			<mass value="0.00001"/>
			<inertia ixx="0.00001" ixy="0.0000" ixz="0.0000" iyy="0.00001" iyz="0.0000" izz="0.00001"/>
		</inertial>
	</link>
	<joint name="seg0_sec4-a-b_joint" type="prismatic">
		<parent link="seg0_sec4-a"/>
		<child link="seg0_sec4-b"/>
		<axis xyz="0 0 -1"/>
		<origin xyz="0 0 0.012"/>
		<limit effort="1000" lower="0" upper="0.012" velocity="1000"/>
	</joint>
	<link name="seg0_sec4-b">
		<visual>
			<geometry>
				<cylinder length="0.024" radius="0.014400000000000001"/>
			</geometry>
			<!-- <origin xyz="0 0 ${length/2}"/> -->
			<material name="green"/>
		</visual>
		<inertial>
			<mass value="0.2"/>
			<inertia ixx="0.0001" ixy="0.000" ixz="0.000" iyy="0.0001" iyz="0.000" izz="0.0001"/>
		</inertial>
	</link>
	<joint name="seg0_sec4-b-seg0-1_connect_joint" type="prismatic">
		<parent link="seg0_sec4-b"/>
		<child link="seg0-1_connect"/>
		<axis xyz="0 0 -1"/>
		<origin xyz="0 0 0.012"/>
		<limit effort="1000" lower="0" upper="0.012" velocity="1000"/>
	</joint>
	<link name="seg0-1_connect">
		<!--since the RBDL needs a inertial info for each link, just assign a really small value to links where we don't have to consider inertia.-->
		<inertial>
			<mass value="0.00001"/>
			<inertia ixx="0.00001" ixy="0.0000" ixz="0.0000" iyy="0.00001" iyz="0.0000" izz="0.00001"/>
		</inertial>
	</link>
	<!--creates a (pseudo) ball joint, called from the PCC macro..-->
	<joint name="seg1_sec0-ball-ball-joint_x_joint" type="revolute">
		<parent link="seg0-1_connect"/>
		<child link="seg1_sec0-ball-ball-joint_link_0"/>
		<axis xyz="1 0 0"/>
		<limit effort="1000" lower="-1.57075" upper="1.57075" velocity="1000"/>
	</joint>
	<link name="seg1_sec0-ball-ball-joint_link_0">
		<!--since the RBDL needs a inertial info for each link, just assign a really small value to links where we don't have to consider inertia.-->
		<inertial>
			<mass value="0.00001"/>
			<inertia ixx="0.00001" ixy="0.0000" ixz="0.0000" iyy="0.00001" iyz="0.0000" izz="0.00001"/>
		</inertial>
	</link>
	<joint name="seg1_sec0-ball-ball-joint_y_joint" type="revolute">
		<parent link="seg1_sec0-ball-ball-joint_link_0"/>
		<child link="seg1_sec0-ball-ball-joint_link_1"/>
		<axis xyz="0 1 0"/>
		<limit effort="1000" lower="-1.57075" upper="1.57075" velocity="1000"/>
	</joint>
	<link name="seg1_sec0-ball-ball-joint_link_1">
		<!--since the RBDL needs a inertial info for each link, just assign a really small value to links where we don't have to consider inertia.-->
		<inertial>
			<mass value="0.00001"/>
			<inertia ixx="0.00001" ixy="0.0000" ixz="0.0000" iyy="0.00001" iyz="0.0000" izz="0.00001"/>
		</inertial>
		<visual>
			<geometry>
				<box size="0.0024000000000000002 0.0024000000000000002 0.0024000000000000002"/>
			</geometry>
			<material name="white"/>
		</visual>
	</link>
	<joint name="seg1_sec0-ball-ball-joint_z_joint" type="revolute">
		<parent link="seg1_sec0-ball-ball-joint_link_1"/>
		<child link="seg1_sec0-a"/>
		<axis xyz="0 0 1"/>
		<limit effort="1000" lower="-1.57075" upper="1.57075" velocity="1000"/>
	</joint>
	<link name="seg1_sec0-a">
		<!--since the RBDL needs a inertial info for each link, just assign a really small value to links where we don't have to consider inertia.-->
		<inertial>
			<mass value="0.00001"/>
			<inertia ixx="0.00001" ixy="0.0000" ixz="0.0000" iyy="0.00001" iyz="0.0000" izz="0.00001"/>
		</inertial>
	</link>
	<joint name="seg1_sec0-a-b_joint" type="prismatic">
		<parent link="seg1_sec0-a"/>
		<child link="seg1_sec0-b"/>
		<axis xyz="0 0 -1"/>
		<origin xyz="0 0 0.012"/>
		<limit effort="1000" lower="0" upper="0.012" velocity="1000"/>
	</joint>
	<link name="seg1_sec0-b">
		<visual>
			<geometry>
				<cylinder length="0.024" radius="0.014000000000000002"/>
			</geometry>
			<!-- <origin xyz="0 0 ${length/2}"/> -->
			<material name="green"/>
		</visual>
		<inertial>
			<mass value="0.2"/>
			<inertia ixx="0.0001" ixy="0.000" ixz="0.000" iyy="0.0001" iyz="0.000" izz="0.0001"/>
		</inertial>
	</link>
	<joint name="seg1_sec0-b-seg1_sec0-1_connect_joint" type="prismatic">
		<parent link="seg1_sec0-b"/>
		<child link="seg1_sec0-1_connect"/>
		<axis xyz="0 0 -1"/>
		<origin xyz="0 0 0.012"/>
		<limit effort="1000" lower="0" upper="0.012" velocity="1000"/>
	</joint>
	<link name="seg1_sec0-1_connect">
		<!--since the RBDL needs a inertial info for each link, just assign a really small value to links where we don't have to consider inertia.-->
		<inertial>
			<mass value="0.00001"/>
			<inertia ixx="0.00001" ixy="0.0000" ixz="0.0000" iyy="0.00001" iyz="0.0000" izz="0.00001"/>
		</inertial>
	</link>
	<!--creates a (pseudo) ball joint, called from the PCC macro..-->
	<joint name="seg1_sec1-ball-ball-joint_x_joint" type="revolute">
		<parent link="seg1_sec0-1_connect"/>
		<child link="seg1_sec1-ball-ball-joint_link_0"/>
		<axis xyz="1 0 0"/>
		<limit effort="1000" lower="-1.57075" upper="1.57075" velocity="1000"/>
	</joint>
	<link name="seg1_sec1-ball-ball-joint_link_0">
		<!--since the RBDL needs a inertial info for each link, just assign a really small value to links where we don't have to consider inertia.-->
		<inertial>
			<mass value="0.00001"/>
			<inertia ixx="0.00001" ixy="0.0000" ixz="0.0000" iyy="0.00001" iyz="0.0000" izz="0.00001"/>
		</inertial>
	</link>
	<joint name="seg1_sec1-ball-ball-joint_y_joint" type="revolute">
		<parent link="seg1_sec1-ball-ball-joint_link_0"/>
		<child link="seg1_sec1-ball-ball-joint_link_1"/>
		<axis xyz="0 1 0"/>
		<limit effort="1000" lower="-1.57075" upper="1.57075" velocity="1000"/>
	</joint>
	<link name="seg1_sec1-ball-ball-joint_link_1">
		<!--since the RBDL needs a inertial info for each link, just assign a really small value to links where we don't have to consider inertia.-->
		<inertial>
			<mass value="0.00001"/>
			<inertia ixx="0.00001" ixy="0.0000" ixz="0.0000" iyy="0.00001" iyz="0.0000" izz="0.00001"/>
		</inertial>
		<visual>
			<geometry>
				<box size="0.0024000000000000002 0.0024000000000000002 0.0024000000000000002"/>
			</geometry>
			<material name="white"/>
		</visual>
	</link>
	<joint name="seg1_sec1-ball-ball-joint_z_joint" type="revolute">
		<parent link="seg1_sec1-ball-ball-joint_link_1"/>
		<child link="seg1_sec1-a"/>
		<axis xyz="0 0 1"/>
		<limit effort="1000" lower="-1.57075" upper="1.57075" velocity="1000"/>
	</joint>
	<link name="seg1_sec1-a">
		<!--since the RBDL needs a inertial info for each link, just assign a really small value to links where we don't have to consider inertia.-->
		<inertial>
			<mass value="0.00001"/>
			<inertia ixx="0.00001" ixy="0.0000" ixz="0.0000" iyy="0.00001" iyz="0.0000" izz="0.00001"/>
		</inertial>
	</link>
	<joint name="seg1_sec1-a-b_joint" type="prismatic">
		<parent link="seg1_sec1-a"/>
		<child link="seg1_sec1-b"/>
		<axis xyz="0 0 -1"/>
		<origin xyz="0 0 0.012"/>
		<limit effort="1000" lower="0" upper="0.012" velocity="1000"/>
	</joint>
	<link name="seg1_sec1-b">
		<visual>
			<geometry>
				<cylinder length="0.024" radius="0.0132"/>
			</geometry>
			<!-- <origin xyz="0 0 ${length/2}"/> -->
			<material name="green"/>
		</visual>
		<inertial>
			<mass value="0.2"/>
			<inertia ixx="0.0001" ixy="0.000" ixz="0.000" iyy="0.0001" iyz="0.000" izz="0.0001"/>
		</inertial>
	</link>
	<joint name="seg1_sec1-b-seg1_sec1-2_connect_joint" type="prismatic">
		<parent link="seg1_sec1-b"/>
		<child link="seg1_sec1-2_connect"/>
		<axis xyz="0 0 -1"/>
		<origin xyz="0 0 0.012"/>
		<limit effort="1000" lower="0" upper="0.012" velocity="1000"/>
	</joint>
	<link name="seg1_sec1-2_connect">
		<!--since the RBDL needs a inertial info for each link, just assign a really small value to links where we don't have to consider inertia.-->
		<inertial>
			<mass value="0.00001"/>
			<inertia ixx="0.00001" ixy="0.0000" ixz="0.0000" iyy="0.00001" iyz="0.0000" izz="0.00001"/>
		</inertial>
	</link>
	<!--creates a (pseudo) ball joint, called from the PCC macro..-->
	<joint name="seg1_sec2-ball-ball-joint_x_joint" type="revolute">
		<parent link="seg1_sec1-2_connect"/>
		<child link="seg1_sec2-ball-ball-joint_link_0"/>
		<axis xyz="1 0 0"/>
		<limit effort="1000" lower="-1.57075" upper="1.57075" velocity="1000"/>
	</joint>
	<link name="seg1_sec2-ball-ball-joint_link_0">
		<!--since the RBDL needs a inertial info for each link, just assign a really small value to links where we don't have to consider inertia.-->
		<inertial>
			<mass value="0.00001"/>
			<inertia ixx="0.00001" ixy="0.0000" ixz="0.0000" iyy="0.00001" iyz="0.0000" izz="0.00001"/>
		</inertial>
	</link>
	<joint name="seg1_sec2-ball-ball-joint_y_joint" type="revolute">
		<parent link="seg1_sec2-ball-ball-joint_link_0"/>
		<child link="seg1_sec2-ball-ball-joint_link_1"/>
		<axis xyz="0 1 0"/>
		<limit effort="1000" lower="-1.57075" upper="1.57075" velocity="1000"/>
	</joint>
	<link name="seg1_sec2-ball-ball-joint_link_1">
		<!--since the RBDL needs a inertial info for each link, just assign a really small value to links where we don't have to consider inertia.-->
		<inertial>
			<mass value="0.00001"/>
			<inertia ixx="0.00001" ixy="0.0000" ixz="0.0000" iyy="0.00001" iyz="0.0000" izz="0.00001"/>
		</inertial>
		<visual>
			<geometry>
				<box size="0.0024000000000000002 0.0024000000000000002 0.0024000000000000002"/>
			</geometry>
			<material name="white"/>
		</visual>
	</link>
	<joint name="seg1_sec2-ball-ball-joint_z_joint" type="revolute">
		<parent link="seg1_sec2-ball-ball-joint_link_1"/>
		<child link="seg1_sec2-a"/>
		<axis xyz="0 0 1"/>
		<limit effort="1000" lower="-1.57075" upper="1.57075" velocity="1000"/>
	</joint>
	<link name="seg1_sec2-a">
		<!--since the RBDL needs a inertial info for each link, just assign a really small value to links where we don't have to consider inertia.-->
		<inertial>
			<mass value="0.00001"/>
			<inertia ixx="0.00001" ixy="0.0000" ixz="0.0000" iyy="0.00001" iyz="0.0000" izz="0.00001"/>
		</inertial>
	</link>
	<joint name="seg1_sec2-a-b_joint" type="prismatic">
		<parent link="seg1_sec2-a"/>
		<child link="seg1_sec2-b"/>
		<axis xyz="0 0 -1"/>
		<origin xyz="0 0 0.012"/>
		<limit effort="1000" lower="0" upper="0.012" velocity="1000"/>
	</joint>
	<link name="seg1_sec2-b">
		<visual>
			<geometry>
				<cylinder length="0.024" radius="0.0124"/>
			</geometry>
			<!-- <origin xyz="0 0 ${length/2}"/> -->
			<material name="green"/>
		</visual>
		<inertial>
			<mass value="0.2"/>
			<inertia ixx="0.0001" ixy="0.000" ixz="0.000" iyy="0.0001" iyz="0.000" izz="0.0001"/>
		</inertial>
	</link>
	<joint name="seg1_sec2-b-seg1_sec2-3_connect_joint" type="prismatic">
		<parent link="seg1_sec2-b"/>
		<child link="seg1_sec2-3_connect"/>
		<axis xyz="0 0 -1"/>
		<origin xyz="0 0 0.012"/>
		<limit effort="1000" lower="0" upper="0.012" velocity="1000"/>
	</joint>
	<link name="seg1_sec2-3_connect">
		<!--since the RBDL needs a inertial info for each link, just assign a really small value to links where we don't have to consider inertia.-->
		<inertial>
			<mass value="0.00001"/>
			<inertia ixx="0.00001" ixy="0.0000" ixz="0.0000" iyy="0.00001" iyz="0.0000" izz="0.00001"/>
		</inertial>
	</link>
	<!--creates a (pseudo) ball joint, called from the PCC macro..-->
	<joint name="seg1_sec3-ball-ball-joint_x_joint" type="revolute">
		<parent link="seg1_sec2-3_connect"/>
		<child link="seg1_sec3-ball-ball-joint_link_0"/>
		<axis xyz="1 0 0"/>
		<limit effort="1000" lower="-1.57075" upper="1.57075" velocity="1000"/>
	</joint>
	<link name="seg1_sec3-ball-ball-joint_link_0">
		<!--since the RBDL needs a inertial info for each link, just assign a really small value to links where we don't have to consider inertia.-->
		<inertial>
			<mass value="0.00001"/>
			<inertia ixx="0.00001" ixy="0.0000" ixz="0.0000" iyy="0.00001" iyz="0.0000" izz="0.00001"/>
		</inertial>
	</link>
	<joint name="seg1_sec3-ball-ball-joint_y_joint" type="revolute">
		<parent link="seg1_sec3-ball-ball-joint_link_0"/>
		<child link="seg1_sec3-ball-ball-joint_link_1"/>
		<axis xyz="0 1 0"/>
		<limit effort="1000" lower="-1.57075" upper="1.57075" velocity="1000"/>
	</joint>
	<link name="seg1_sec3-ball-ball-joint_link_1">
		<!--since the RBDL needs a inertial info for each link, just assign a really small value to links where we don't have to consider inertia.-->
		<inertial>
			<mass value="0.00001"/>
			<inertia ixx="0.00001" ixy="0.0000" ixz="0.0000" iyy="0.00001" iyz="0.0000" izz="0.00001"/>
		</inertial>
		<visual>
			<geometry>
				<box size="0.0024000000000000002 0.0024000000000000002 0.0024000000000000002"/>
			</geometry>
			<material name="white"/>
		</visual>
	</link>
	<joint name="seg1_sec3-ball-ball-joint_z_joint" type="revolute">
		<parent link="seg1_sec3-ball-ball-joint_link_1"/>
		<child link="seg1_sec3-a"/>
		<axis xyz="0 0 1"/>
		<limit effort="1000" lower="-1.57075" upper="1.57075" velocity="1000"/>
	</joint>
	<link name="seg1_sec3-a">
		<!--since the RBDL needs a inertial info for each link, just assign a really small value to links where we don't have to consider inertia.-->
		<inertial>
			<mass value="0.00001"/>
			<inertia ixx="0.00001" ixy="0.0000" ixz="0.0000" iyy="0.00001" iyz="0.0000" izz="0.00001"/>
		</inertial>
	</link>
	<joint name="seg1_sec3-a-b_joint" type="prismatic">
		<parent link="seg1_sec3-a"/>
		<child link="seg1_sec3-b"/>
		<axis xyz="0 0 -1"/>
		<origin xyz="0 0 0.012"/>
		<limit effort="1000" lower="0" upper="0.012" velocity="1000"/>
	</joint>
	<link name="seg1_sec3-b">
		<visual>
			<geometry>
				<cylinder length="0.024" radius="0.0116"/>
			</geometry>
			<!-- <origin xyz="0 0 ${length/2}"/> -->
			<material name="green"/>
		</visual>
		<inertial>
			<mass value="0.2"/>
			<inertia ixx="0.0001" ixy="0.000" ixz="0.000" iyy="0.0001" iyz="0.000" izz="0.0001"/>
		</inertial>
	</link>
	<joint name="seg1_sec3-b-seg1_sec3-4_connect_joint" type="prismatic">
		<parent link="seg1_sec3-b"/>
		<child link="seg1_sec3-4_connect"/>
		<axis xyz="0 0 -1"/>
		<origin xyz="0 0 0.012"/>
		<limit effort="1000" lower="0" upper="0.012" velocity="1000"/>
	</joint>
	<link name="seg1_sec3-4_connect">
		<!--since the RBDL needs a inertial info for each link, just assign a really small value to links where we don't have to consider inertia.-->
		<inertial>
			<mass value="0.00001"/>
			<inertia ixx="0.00001" ixy="0.0000" ixz="0.0000" iyy="0.00001" iyz="0.0000" izz="0.00001"/>
		</inertial>
	</link>
	<!--creates a (pseudo) ball joint, called from the PCC macro..-->
	<joint name="seg1_sec4-ball-ball-joint_x_joint" type="revolute">
		<parent link="seg1_sec3-4_connect"/>
		<child link="seg1_sec4-ball-ball-joint_link_0"/>
		<axis xyz="1 0 0"/>
		<limit effort="1000" lower="-1.57075" upper="1.57075" velocity="1000"/>
	</joint>
	<link name="seg1_sec4-ball-ball-joint_link_0">
		<!--since the RBDL needs a inertial info for each link, just assign a really small value to links where we don't have to consider inertia.-->
		<inertial>
			<mass value="0.00001"/>
			<inertia ixx="0.00001" ixy="0.0000" ixz="0.0000" iyy="0.00001" iyz="0.0000" izz="0.00001"/>
		</inertial>
	</link>
	<joint name="seg1_sec4-ball-ball-joint_y_joint" type="revolute">
		<parent link="seg1_sec4-ball-ball-joint_link_0"/>
		<child link="seg1_sec4-ball-ball-joint_link_1"/>
		<axis xyz="0 1 0"/>
		<limit effort="1000" lower="-1.57075" upper="1.57075" velocity="1000"/>
	</joint>
	<link name="seg1_sec4-ball-ball-joint_link_1">
		<!--since the RBDL needs a inertial info for each link, just assign a really small value to links where we don't have to consider inertia.-->
		<inertial>
			<mass value="0.00001"/>
			<inertia ixx="0.00001" ixy="0.0000" ixz="0.0000" iyy="0.00001" iyz="0.0000" izz="0.00001"/>
		</inertial>
		<visual>
			<geometry>
				<box size="0.0024000000000000002 0.0024000000000000002 0.0024000000000000002"/>
			</geometry>
			<material name="white"/>
		</visual>
	</link>
	<joint name="seg1_sec4-ball-ball-joint_z_joint" type="revolute">
		<parent link="seg1_sec4-ball-ball-joint_link_1"/>
		<child link="seg1_sec4-a"/>
		<axis xyz="0 0 1"/>
		<limit effort="1000" lower="-1.57075" upper="1.57075" velocity="1000"/>
	</joint>
	<link name="seg1_sec4-a">
		<!--since the RBDL needs a inertial info for each link, just assign a really small value to links where we don't have to consider inertia.-->
		<inertial>
			<mass value="0.00001"/>
			<inertia ixx="0.00001" ixy="0.0000" ixz="0.0000" iyy="0.00001" iyz="0.0000" izz="0.00001"/>
		</inertial>
	</link>
	<joint name="seg1_sec4-a-b_joint" type="prismatic">
		<parent link="seg1_sec4-a"/>
		<child link="seg1_sec4-b"/>
		<axis xyz="0 0 -1"/>
		<origin xyz="0 0 0.012"/>
		<limit effort="1000" lower="0" upper="0.012" velocity="1000"/>
	</joint>
	<link name="seg1_sec4-b">
		<visual>
			<geometry>
				<cylinder length="0.024" radius="0.0108"/>
			</geometry>
			<!-- <origin xyz="0 0 ${length/2}"/> -->
			<material name="green"/>
		</visual>
		<inertial>
			<mass value="0.2"/>
			<inertia ixx="0.0001" ixy="0.000" ixz="0.000" iyy="0.0001" iyz="0.000" izz="0.0001"/>
		</inertial>
	</link>
	<joint name="seg1_sec4-b-seg1-2_connect_joint" type="prismatic">
		<parent link="seg1_sec4-b"/>
		<child link="seg1-2_connect"/>
		<axis xyz="0 0 -1"/>
		<origin xyz="0 0 0.012"/>
		<limit effort="1000" lower="0" upper="0.012" velocity="1000"/>
	</joint>
	<link name="seg1-2_connect">
		<!--since the RBDL needs a inertial info for each link, just assign a really small value to links where we don't have to consider inertia.-->
		<inertial>
			<mass value="0.00001"/>
			<inertia ixx="0.00001" ixy="0.0000" ixz="0.0000" iyy="0.00001" iyz="0.0000" izz="0.00001"/>
		</inertial>
	</link>
</robot>
